Workbook

Sheet AMZN
A1: Date giornaliere | B1: Prezzi giornalieri AMZN | C1: Rendimenti giornalieri AMZN | E1: Date mensili | F1: Prezzi mensili AMZN | G1: Rendimenti mensili AMZN | I1: Date annuali | J1: Prezzi annuali AMZN | K1: Rendimento annuale AMZN
A2: 35565 | B2: 0.0979 | C2: 0 | E2: 35581 | F2: =VLOOKUP(E2,A:B,2,TRUE) -> 0.075 | G2: 0 | I2: 35795 | J2: =VLOOKUP(I2, E:F, 2, TRUE) -> 0.251 | K2: 0
A3: 35566 | B3: 0.0865 | C3: =(AMZN[[#This Row],[Prezzi giornalieri AMZN]]-B2)/B2 -> -0.11644535 | E3: 35611 | F3: =VLOOKUP(E3,A:B,2,TRUE) -> 0.0771 | G3: =(F3-F2)/F2 -> 0.028 | I3: 36160 | J3: =VLOOKUP(I3, E:F, 2, TRUE) -> 2.6771 | K3: =(J3-J2)/J2 -> 9.6657371
A4: 35569 | B4: 0.0854 | C4: =(AMZN[[#This Row],[Prezzi giornalieri AMZN]]-B3)/B3 -> -0.012716763 | E4: 35642 | F4: =VLOOKUP(E4,A:B,2,TRUE) -> 0.1198 | G4: =(F4-F3)/F3 -> 0.5538262 | I4: 36525 | J4: =VLOOKUP(I4, E:F, 2, TRUE) -> 3.8063 | K4: =(J4-J3)/J3 -> 0.42179971
A5: 35570 | B5: 0.0818 | C5: =(AMZN[[#This Row],[Prezzi giornalieri AMZN]]-B4)/B4 -> -0.042154567 | E5: 35673 | F5: =VLOOKUP(E5,A:B,2,TRUE) -> 0.1169 | G5: =(F5-F4)/F4 -> -0.024207012 | I5: 36891 | J5: =VLOOKUP(I5, E:F, 2, TRUE) -> 0.7781 | K5: =(J5-J4)/J4 -> -0.79557576
A6: 35571 | B6: 0.0714 | C6: =(AMZN[[#This Row],[Prezzi giornalieri AMZN]]-B5)/B5 -> -0.12713936 | E6: 35703 | F6: =VLOOKUP(E6,A:B,2,TRUE) -> 0.2169 | G6: =(F6-F5)/F5 -> 0.85543199 | I6: 37256 | J6: =VLOOKUP(I6, E:F, 2, TRUE) -> 0.541 | K6: =(J6-J5)/J5 -> -0.30471662
A7: 35572 | B7: 0.0698 | C7: =(AMZN[[#This Row],[Prezzi giornalieri AMZN]]-B6)/B6 -> -0.022408964 | E7: 35734 | F7: =VLOOKUP(E7,A:B,2,TRUE) -> 0.2542 | G7: =(F7-F6)/F6 -> 0.17196865 | I7: 37621 | J7: =VLOOKUP(I7, E:F, 2, TRUE) -> 0.9445 | K7: =(J7-J6)/J6 -> 0.74584104
A8: 35573 | B8: 0.075 | C8: =(AMZN[[#This Row],[Prezzi giornalieri AMZN]]-B7)/B7 -> 0.074498567 | E8: 35764 | F8: =VLOOKUP(E8,A:B,2,TRUE) -> 0.2062 | G8: =(F8-F7)/F7 -> -0.18882769 | I8: 37986 | J8: =VLOOKUP(I8, E:F, 2, TRUE) -> 2.631 | K8: =(J8-J7)/J7 -> 1.7856008
A9: 35577 | B9: 0.0792 | C9: =(AMZN[[#This Row],[Prezzi giornalieri AMZN]]-B8)/B8 -> 0.056 | E9: 35795 | F9: =VLOOKUP(E9,A:B,2,TRUE) -> 0.251 | G9: =(F9-F8)/F8 -> 0.21726479 | I9: 38352 | J9: =VLOOKUP(I9, E:F, 2, TRUE) -> 2.2145 | K9: =(J9-J8)/J8 -> -0.15830483
A10: 35578 | B10: 0.0766 | C10: =(AMZN[[#This Row],[Prezzi giornalieri AMZN]]-B9)/B9 -> -0.032828283 | E10: 35826 | F10: =VLOOKUP(E10,A:B,2,TRUE) -> 0.2458 | G10: =(F10-F9)/F9 -> -0.020717131 | I10: 38717 | J10: =VLOOKUP(I10, E:F, 2, TRUE) -> 2.3575 | K10: =(J10-J9)/J9 -> 0.064574396
A11: 35579 | B11: 0.0753 | C11: =(AMZN[[#This Row],[Prezzi giornalieri AMZN]]-B10)/B10 -> -0.016971279 | E11: 35854 | F11: =VLOOKUP(E11,A:B,2,TRUE) -> 0.3208 | G11: =(F11-F10)/F10 -> 0.30512612 | I11: 39082 | J11: =VLOOKUP(I11, E:F, 2, TRUE) -> 1.973 | K11: =(J11-J10)/J10 -> -0.1630965
A12: 35580 | B12: 0.075 | C12: =(AMZN[[#This Row],[Prezzi giornalieri AMZN]]-B11)/B11 -> -0.0039840637 | E12: 35885 | F12: =VLOOKUP(E12,A:B,2,TRUE) -> 0.3564 | G12: =(F12-F11)/F11 -> 0.11097257 | I12: 39447 | J12: =VLOOKUP(I12, E:F, 2, TRUE) -> 4.632 | K12: =(J12-J11)/J11 -> 1.3476939
A13: 35583 | B13: 0.0755 | C13: =(AMZN[[#This Row],[Prezzi giornalieri AMZN]]-B12)/B12 -> 0.0066666667 | E13: 35915 | F13: =VLOOKUP(E13,A:B,2,TRUE) -> 0.3823 | G13: =(F13-F12)/F12 -> 0.072671156 | I13: 39813 | J13: =VLOOKUP(I13, E:F, 2, TRUE) -> 2.564 | K13: =(J13-J12)/J12 -> -0.44645941
A14: 35584 | B14: 0.074 | C14: =(AMZN[[#This Row],[Prezzi giornalieri AMZN]]-B13)/B13 -> -0.01986755 | E14: 35946 | F14: =VLOOKUP(E14,A:B,2,TRUE) -> 0.3672 | G14: =(F14-F13)/F13 -> -0.039497777 | I14: 40178 | J14: =VLOOKUP(I14, E:F, 2, TRUE) -> 6.726 | K14: =(J14-J13)/J13 -> 1.6232449
... A30: 35606 | B30: 0.0755 | C30: =(AMZN[[#This Row],[Prezzi giornalieri AMZN]]-B29)/B29 -> 0 | E30: 36433 | F30: =VLOOKUP(E30,A:B,2,TRUE) -> 3.9969 | G30: =(F30-F29)/F29 -> 0.28542484 | I30: 46022 | J30: =VLOOKUP(I30, E:F, 2, TRUE) -> 212.52 | K30: =(J30-J29)/J29 -> -0.031314098
A31: 35607 | B31: 0.0755 | C31: =(AMZN[[#This Row],[Prezzi giornalieri AMZN]]-B30)/B30 -> 0 | E31: 36464 | F31: =VLOOKUP(E31,A:B,2,TRUE) -> 3.5312 | G31: =(F31-F30)/F30 -> -0.1165153
A32: 35608 | B32: 0.0745 | C32: =(AMZN[[#This Row],[Prezzi giornalieri AMZN]]-B31)/B31 -> -0.013245033 | E32: 36494 | F32: =VLOOKUP(E32,A:B,2,TRUE) -> 4.2531 | G32: =(F32-F31)/F31 -> 0.20443475
A33: 35611 | B33: 0.0771 | C33: =(AMZN[[#This Row],[Prezzi giornalieri AMZN]]-B32)/B32 -> 0.034899329 | E33: 36525 | F33: =VLOOKUP(E33,A:B,2,TRUE) -> 3.8063 | G33: =(F33-F32)/F32 -> -0.10505279
A34: 35612 | B34: 0.0758 | C34: =(AMZN[[#This Row],[Prezzi giornalieri AMZN]]-B33)/B33 -> -0.016861219 | E34: 36556 | F34: =VLOOKUP(E34,A:B,2,TRUE) -> 3.2281 | G34: =(F34-F33)/F33 -> -0.15190605
A35: 35613 | B35: 0.0794 | C35: =(AMZN[[#This Row],[Prezzi giornalieri AMZN]]-B34)/B34 -> 0.047493404 | E35: 36585 | F35: =VLOOKUP(E35,A:B,2,TRUE) -> 3.4437 | G35: =(F35-F34)/F34 -> 0.066788513
A36: 35614 | B36: 0.0956 | C36: =(AMZN[[#This Row],[Prezzi giornalieri AMZN]]-B35)/B35 -> 0.20403023 | E36: 36616 | F36: =VLOOKUP(E36,A:B,2,TRUE) -> 3.35 | G36: =(F36-F35)/F35 -> -0.027209106
A37: 35618 | B37: 0.1 | C37: =(AMZN[[#This Row],[Prezzi giornalieri AMZN]]-B36)/B36 -> 0.046025105 | E37: 36646 | F37: =VLOOKUP(E37,A:B,2,TRUE) -> 2.7594 | G37: =(F37-F36)/F36 -> -0.17629851
A38: 35619 | B38: 0.1151 | C38: =(AMZN[[#This Row],[Prezzi giornalieri AMZN]]-B37)/B37 -> 0.151 | E38: 36677 | F38: =VLOOKUP(E38,A:B,2,TRUE) -> 2.4156 | G38: =(F38-F37)/F37 -> -0.1245923
A39: 35620 | B39: 0.1161 | C39: =(AMZN[[#This Row],[Prezzi giornalieri AMZN]]-B38)/B38 -> 0.0086880973 | E39: 36707 | F39: =VLOOKUP(E39,A:B,2,TRUE) -> 1.8156 | G39: =(F39-F38)/F38 -> -0.24838549
A40: 35621 | B40: 0.1281 | C40: =(AMZN[[#This Row],[Prezzi giornalieri AMZN]]-B39)/B39 -> 0.10335917 | E40: 36738 | F40: =VLOOKUP(E40,A:B,2,TRUE) -> 1.5063 | G40: =(F40-F39)/F39 -> -0.17035691
A41: 35622 | B41: 0.1146 | C41: =(AMZN[[#This Row],[Prezzi giornalieri AMZN]]-B40)/B40 -> -0.10538642 | E41: 36769 | F41: =VLOOKUP(E41,A:B,2,TRUE) -> 2.075 | G41: =(F41-F40)/F40 -> 0.37754763
A42: 35625 | B42: 0.1068 | C42: =(AMZN[[#This Row],[Prezzi giornalieri AMZN]]-B41)/B41 -> -0.068062827 | E42: 36799 | F42: =VLOOKUP(E42,A:B,2,TRUE) -> 1.9219 | G42: =(F42-F41)/F41 -> -0.073783133
... A339: 36054 | B339: 0.7042 | C339: =(AMZN[[#This Row],[Prezzi giornalieri AMZN]]-B338)/B338 -> 0.15765247 | E339: 45838 | F339: =VLOOKUP(E339,A:B,2,TRUE) -> 212.52 | G339: =(F339-F338)/F338 -> 0.036632359
A340: 36055 | B340: 0.6417 | C340: =(AMZN[[#This Row],[Prezzi giornalieri AMZN]]-B339)/B339 -> -0.088753195
A341: 36056 | B341: 0.6641 | C341: =(AMZN[[#This Row],[Prezzi giornalieri AMZN]]-B340)/B340 -> 0.034907278
A342: 36059 | B342: 0.7125 | C342: =(AMZN[[#This Row],[Prezzi giornalieri AMZN]]-B341)/B341 -> 0.07288059
A343: 36060 | B343: 0.7349 | C343: =(AMZN[[#This Row],[Prezzi giornalieri AMZN]]-B342)/B342 -> 0.031438596
A344: 36061 | B344: 0.876 | C344: =(AMZN[[#This Row],[Prezzi giornalieri AMZN]]-B343)/B343 -> 0.19199891
A345: 36062 | B345: 0.851 | C345: =(AMZN[[#This Row],[Prezzi giornalieri AMZN]]-B344)/B344 -> -0.028538813
A346: 36063 | B346: 0.9104 | C346: =(AMZN[[#This Row],[Prezzi giornalieri AMZN]]-B345)/B345 -> 0.069800235
A347: 36066 | B347: 0.9635 | C347: =(AMZN[[#This Row],[Prezzi giornalieri AMZN]]-B346)/B346 -> 0.058326011
A348: 36067 | B348: 0.9427 | C348: =(AMZN[[#This Row],[Prezzi giornalieri AMZN]]-B347)/B347 -> -0.021587961
A349: 36068 | B349: 0.9302 | C349: =(AMZN[[#This Row],[Prezzi giornalieri AMZN]]-B348)/B348 -> -0.013259786
A350: 36069 | B350: 0.8552 | C350: =(AMZN[[#This Row],[Prezzi giornalieri AMZN]]-B349)/B349 -> -0.080627822
A351: 36070 | B351: 0.9187 | C351: =(AMZN[[#This Row],[Prezzi giornalieri AMZN]]-B350)/B350 -> 0.074251637
...

Sheet MSFT
A1: Date giornaliere | B1: Prezzi giornalieri MSFT | C1: Rendimenti giornalieri MSFT | E1: Date mensili | F1: Prezzi mensili MSFT | G1: Rendimenti mensili MSFT | I1: Date annuali | J1: Prezzi annuali MSFT | K1: Rendimenti annuali MSFT
A2: 31484 | B2: 0.06 | C2: 0 | E2: 31502 | F2: =VLOOKUP(E2,A:B,2,TRUE) -> 0.06 | G2: 0 | I2: 31777 | J2: =VLOOKUP(I2, E:F, 2, TRUE) -> 0.1 | K2: 0
A3: 31485 | B3: 0.06 | C3: =(MSFT[[#This Row],[Prezzi giornalieri MSFT]]-B2)/B2 -> 0 | E3: 31532 | F3: =VLOOKUP(E3,A:B,2,TRUE) -> 0.07 | G3: =(F3-F2)/F2 -> 0.16666667 | I3: 32142 | J3: =VLOOKUP(I3, E:F, 2, TRUE) -> 0.23 | K3: =(J3-J2)/J2 -> 1.3
A4: 31488 | B4: 0.06 | C4: =(MSFT[[#This Row],[Prezzi giornalieri MSFT]]-B3)/B3 -> 0 | E4: 31563 | F4: =VLOOKUP(E4,A:B,2,TRUE) -> 0.07 | G4: =(F4-F3)/F3 -> 0 | I4: 32508 | J4: =VLOOKUP(I4, E:F, 2, TRUE) -> 0.23 | K4: =(J4-J3)/J3 -> 0
A5: 31489 | B5: 0.06 | C5: =(MSFT[[#This Row],[Prezzi giornalieri MSFT]]-B4)/B4 -> 0 | E5: 31593 | F5: =VLOOKUP(E5,A:B,2,TRUE) -> 0.07 | G5: =(F5-F4)/F4 -> 0 | I5: 32873 | J5: =VLOOKUP(I5, E:F, 2, TRUE) -> 0.37 | K5: =(J5-J4)/J4 -> 0.60869565
A6: 31490 | B6: 0.06 | C6: =(MSFT[[#This Row],[Prezzi giornalieri MSFT]]-B5)/B5 -> 0 | E6: 31624 | F6: =VLOOKUP(E6,A:B,2,TRUE) -> 0.06 | G6: =(F6-F5)/F5 -> -0.14285714 | I6: 33238 | J6: =VLOOKUP(I6, E:F, 2, TRUE) -> 0.64 | K6: =(J6-J5)/J5 -> 0.72972973
A7: 31491 | B7: 0.06 | C7: =(MSFT[[#This Row],[Prezzi giornalieri MSFT]]-B6)/B6 -> 0 | E7: 31655 | F7: =VLOOKUP(E7,A:B,2,TRUE) -> 0.06 | G7: =(F7-F6)/F6 -> 0 | I7: 33603 | J7: =VLOOKUP(I7, E:F, 2, TRUE) -> 1.42 | K7: =(J7-J6)/J6 -> 1.21875
A8: 31492 | B8: 0.06 | C8: =(MSFT[[#This Row],[Prezzi giornalieri MSFT]]-B7)/B7 -> 0 | E8: 31685 | F8: =VLOOKUP(E8,A:B,2,TRUE) -> 0.06 | G8: =(F8-F7)/F7 -> 0 | I8: 33969 | J8: =VLOOKUP(I8, E:F, 2, TRUE) -> 1.64 | K8: =(J8-J7)/J7 -> 0.15492958
A9: 31495 | B9: 0.06 | C9: =(MSFT[[#This Row],[Prezzi giornalieri MSFT]]-B8)/B8 -> 0 | E9: 31716 | F9: =VLOOKUP(E9,A:B,2,TRUE) -> 0.08 | G9: =(F9-F8)/F8 -> 0.33333333 | I9: 34334 | J9: =VLOOKUP(I9, E:F, 2, TRUE) -> 1.54 | K9: =(J9-J8)/J8 -> -0.06097561
A10: 31496 | B10: 0.06 | C10: =(MSFT[[#This Row],[Prezzi giornalieri MSFT]]-B9)/B9 -> 0 | E10: 31746 | F10: =VLOOKUP(E10,A:B,2,TRUE) -> 0.11 | G10: =(F10-F9)/F9 -> 0.375 | I10: 34699 | J10: =VLOOKUP(I10, E:F, 2, TRUE) -> 2.34 | K10: =(J10-J9)/J9 -> 0.51948052
A11: 31497 | B11: 0.06 | C11: =(MSFT[[#This Row],[Prezzi giornalieri MSFT]]-B10)/B10 -> 0 | E11: 31777 | F11: =VLOOKUP(E11,A:B,2,TRUE) -> 0.1 | G11: =(F11-F10)/F10 -> -0.090909091 | I11: 35064 | J11: =VLOOKUP(I11, E:F, 2, TRUE) -> 3.36 | K11: =(J11-J10)/J10 -> 0.43589744
A12: 31498 | B12: 0.06 | C12: =(MSFT[[#This Row],[Prezzi giornalieri MSFT]]-B11)/B11 -> 0 | E12: 31808 | F12: =VLOOKUP(E12,A:B,2,TRUE) -> 0.16 | G12: =(F12-F11)/F11 -> 0.6 | I12: 35430 | J12: =VLOOKUP(I12, E:F, 2, TRUE) -> 6.33 | K12: =(J12-J11)/J11 -> 0.88392857
A13: 31502 | B13: 0.06 | C13: =(MSFT[[#This Row],[Prezzi giornalieri MSFT]]-B12)/B12 -> 0 | E13: 31836 | F13: =VLOOKUP(E13,A:B,2,TRUE) -> 0.16 | G13: =(F13-F12)/F12 -> 0 | I13: 35795 | J13: =VLOOKUP(I13, E:F, 2, TRUE) -> 9.9 | K13: =(J13-J12)/J12 -> 0.56398104
A14: 31503 | B14: 0.06 | C14: =(MSFT[[#This Row],[Prezzi giornalieri MSFT]]-B13)/B13 -> 0 | E14: 31867 | F14: =VLOOKUP(E14,A:B,2,TRUE) -> 0.21 | G14: =(F14-F13)/F13 -> 0.3125 | I14: 36160 | J14: =VLOOKUP(I14, E:F, 2, TRUE) -> 21.25 | K14: =(J14-J13)/J13 -> 1.1464646
... A41: 31540 | B41: 0.07 | C41: =(MSFT[[#This Row],[Prezzi giornalieri MSFT]]-B40)/B40 -> 0 | E41: 32689 | F41: =VLOOKUP(E41,A:B,2,TRUE) -> 0.23 | G41: =(F41-F40)/F40 -> -0.11538462 | I41: 46022 | J41: =VLOOKUP(I41, E:F, 2, TRUE) -> 480.24 | K41: =(J41-J40)/J40 -> 0.14372812
A42: 31541 | B42: 0.07 | C42: =(MSFT[[#This Row],[Prezzi giornalieri MSFT]]-B41)/B41 -> 0 | E42: 32720 | F42: =VLOOKUP(E42,A:B,2,TRUE) -> 0.23 | G42: =(F42-F41)/F41 -> 0
A43: 31544 | B43: 0.07 | C43: =(MSFT[[#This Row],[Prezzi giornalieri MSFT]]-B42)/B42 -> 0 | E43: 32751 | F43: =VLOOKUP(E43,A:B,2,TRUE) -> 0.25 | G43: =(F43-F42)/F42 -> 0.086956522
A44: 31545 | B44: 0.07 | C44: =(MSFT[[#This Row],[Prezzi giornalieri MSFT]]-B43)/B43 -> 0 | E44: 32781 | F44: =VLOOKUP(E44,A:B,2,TRUE) -> 0.29 | G44: =(F44-F43)/F43 -> 0.16
A45: 31546 | B45: 0.07 | C45: =(MSFT[[#This Row],[Prezzi giornalieri MSFT]]-B44)/B44 -> 0 | E45: 32812 | F45: =VLOOKUP(E45,A:B,2,TRUE) -> 0.35 | G45: =(F45-F44)/F44 -> 0.20689655
A46: 31547 | B46: 0.07 | C46: =(MSFT[[#This Row],[Prezzi giornalieri MSFT]]-B45)/B45 -> 0 | E46: 32842 | F46: =VLOOKUP(E46,A:B,2,TRUE) -> 0.37 | G46: =(F46-F45)/F45 -> 0.057142857
A47: 31548 | B47: 0.07 | C47: =(MSFT[[#This Row],[Prezzi giornalieri MSFT]]-B46)/B46 -> 0 | E47: 32873 | F47: =VLOOKUP(E47,A:B,2,TRUE) -> 0.37 | G47: =(F47-F46)/F46 -> 0
A48: 31551 | B48: 0.07 | C48: =(MSFT[[#This Row],[Prezzi giornalieri MSFT]]-B47)/B47 -> 0 | E48: 32904 | F48: =VLOOKUP(E48,A:B,2,TRUE) -> 0.39 | G48: =(F48-F47)/F47 -> 0.054054054
A49: 31552 | B49: 0.07 | C49: =(MSFT[[#This Row],[Prezzi giornalieri MSFT]]-B48)/B48 -> 0 | E49: 32932 | F49: =VLOOKUP(E49,A:B,2,TRUE) -> 0.42 | G49: =(F49-F48)/F48 -> 0.076923077
A50: 31553 | B50: 0.07 | C50: =(MSFT[[#This Row],[Prezzi giornalieri MSFT]]-B49)/B49 -> 0 | E50: 32963 | F50: =VLOOKUP(E50,A:B,2,TRUE) -> 0.47 | G50: =(F50-F49)/F49 -> 0.11904762
A51: 31554 | B51: 0.07 | C51: =(MSFT[[#This Row],[Prezzi giornalieri MSFT]]-B50)/B50 -> 0 | E51: 32993 | F51: =VLOOKUP(E51,A:B,2,TRUE) -> 0.49 | G51: =(F51-F50)/F50 -> 0.042553191
A52: 31555 | B52: 0.07 | C52: =(MSFT[[#This Row],[Prezzi giornalieri MSFT]]-B51)/B51 -> 0 | E52: 33024 | F52: =VLOOKUP(E52,A:B,2,TRUE) -> 0.62 | G52: =(F52-F51)/F51 -> 0.26530612
A53: 31559 | B53: 0.07 | C53: =(MSFT[[#This Row],[Prezzi giornalieri MSFT]]-B52)/B52 -> 0 | E53: 33054 | F53: =VLOOKUP(E53,A:B,2,TRUE) -> 0.65 | G53: =(F53-F52)/F52 -> 0.048387097
... A473: 32164 | B473: 0.23 | C473: =(MSFT[[#This Row],[Prezzi giornalieri MSFT]]-B472)/B472 -> 0 | E473: 45838 | F473: =VLOOKUP(E473,A:B,2,TRUE) -> 480.24 | G473: =(F473-F472)/F472 -> 0.043183595
A474: 32167 | B474: 0.24 | C474: =(MSFT[[#This Row],[Prezzi giornalieri MSFT]]-B473)/B473 -> 0.043478261
A475: 32168 | B475: 0.23 | C475: =(MSFT[[#This Row],[Prezzi giornalieri MSFT]]-B474)/B474 -> -0.041666667
A476: 32169 | B476: 0.24 | C476: =(MSFT[[#This Row],[Prezzi giornalieri MSFT]]-B475)/B475 -> 0.043478261
A477: 32170 | B477: 0.24 | C477: =(MSFT[[#This Row],[Prezzi giornalieri MSFT]]-B476)/B476 -> 0
A478: 32171 | B478: 0.24 | C478: =(MSFT[[#This Row],[Prezzi giornalieri MSFT]]-B477)/B477 -> 0
A479: 32174 | B479: 0.24 | C479: =(MSFT[[#This Row],[Prezzi giornalieri MSFT]]-B478)/B478 -> 0
A480: 32175 | B480: 0.24 | C480: =(MSFT[[#This Row],[Prezzi giornalieri MSFT]]-B479)/B479 -> 0
A481: 32176 | B481: 0.22 | C481: =(MSFT[[#This Row],[Prezzi giornalieri MSFT]]-B480)/B480 -> -0.083333333
A482: 32177 | B482: 0.22 | C482: =(MSFT[[#This Row],[Prezzi giornalieri MSFT]]-B481)/B481 -> 0
A483: 32178 | B483: 0.22 | C483: =(MSFT[[#This Row],[Prezzi giornalieri MSFT]]-B482)/B482 -> 0
A484: 32181 | B484: 0.22 | C484: =(MSFT[[#This Row],[Prezzi giornalieri MSFT]]-B483)/B483 -> 0
A485: 32182 | B485: 0.22 | C485: =(MSFT[[#This Row],[Prezzi giornalieri MSFT]]-B484)/B484 -> 0
...

Sheet TSLA
A1: Date giornaliere | B1: Prezzi giornalieri TSLA | C1: Rendimenti giornalieri TSLA | E1: Date mensili | F1: Prezzi mensili TSLA | G1: Rendimenti mensili TSLA | I1: Date annuali | J1: Prezzi annuali TSLA | K1: Rendimento annuale TSLA
A2: 40358 | B2: 1.59 | C2: 0 | E2: 40359 | F2: =VLOOKUP(E2,A:B,2,TRUE) -> 1.59 | G2: 0 | I2: 40543 | J2: =VLOOKUP(I2, E:F, 2, TRUE) -> 1.78 | K2: 0
A3: 40359 | B3: 1.59 | C3: =(TSLA[[#This Row],[Prezzi giornalieri TSLA]]-B2)/B2 -> 0 | E3: 40390 | F3: =VLOOKUP(E3,A:B,2,TRUE) -> 1.33 | G3: =(F3-F2)/F2 -> -0.16352201 | I3: 40908 | J3: =VLOOKUP(I3, E:F, 2, TRUE) -> 1.9 | K3: =(J3-J2)/J2 -> 0.06741573
A4: 40360 | B4: 1.46 | C4: =(TSLA[[#This Row],[Prezzi giornalieri TSLA]]-B3)/B3 -> -0.081761006 | E4: 40421 | F4: =VLOOKUP(E4,A:B,2,TRUE) -> 1.3 | G4: =(F4-F3)/F3 -> -0.022556391 | I4: 41274 | J4: =VLOOKUP(I4, E:F, 2, TRUE) -> 2.26 | K4: =(J4-J3)/J3 -> 0.18947368
A5: 40361 | B5: 1.28 | C5: =(TSLA[[#This Row],[Prezzi giornalieri TSLA]]-B4)/B4 -> -0.12328767 | E5: 40451 | F5: =VLOOKUP(E5,A:B,2,TRUE) -> 1.36 | G5: =(F5-F4)/F4 -> 0.046153846 | I5: 41639 | J5: =VLOOKUP(I5, E:F, 2, TRUE) -> 10.03 | K5: =(J5-J4)/J4 -> 3.4380531
A6: 40365 | B6: 1.07 | C6: =(TSLA[[#This Row],[Prezzi giornalieri TSLA]]-B5)/B5 -> -0.1640625 | E6: 40482 | F6: =VLOOKUP(E6,A:B,2,TRUE) -> 1.46 | G6: =(F6-F5)/F5 -> 0.073529412 | I6: 42004 | J6: =VLOOKUP(I6, E:F, 2, TRUE) -> 14.83 | K6: =(J6-J5)/J5 -> 0.47856431
A7: 40366 | B7: 1.05 | C7: =(TSLA[[#This Row],[Prezzi giornalieri TSLA]]-B6)/B6 -> -0.018691589 | E7: 40512 | F7: =VLOOKUP(E7,A:B,2,TRUE) -> 2.36 | G7: =(F7-F6)/F6 -> 0.61643836 | I7: 42369 | J7: =VLOOKUP(I7, E:F, 2, TRUE) -> 16 | K7: =(J7-J6)/J6 -> 0.078894134
A8: 40367 | B8: 1.16 | C8: =(TSLA[[#This Row],[Prezzi giornalieri TSLA]]-B7)/B7 -> 0.1047619 | E8: 40543 | F8: =VLOOKUP(E8,A:B,2,TRUE) -> 1.78 | G8: =(F8-F7)/F7 -> -0.24576271 | I8: 42735 | J8: =VLOOKUP(I8, E:F, 2, TRUE) -> 14.25 | K8: =(J8-J7)/J7 -> -0.109375
A9: 40368 | B9: 1.16 | C9: =(TSLA[[#This Row],[Prezzi giornalieri TSLA]]-B8)/B8 -> 0 | E9: 40574 | F9: =VLOOKUP(E9,A:B,2,TRUE) -> 1.61 | G9: =(F9-F8)/F8 -> -0.095505618 | I9: 43100 | J9: =VLOOKUP(I9, E:F, 2, TRUE) -> 20.76 | K9: =(J9-J8)/J8 -> 0.45684211
A10: 40371 | B10: 1.14 | C10: =(TSLA[[#This Row],[Prezzi giornalieri TSLA]]-B9)/B9 -> -0.017241379 | E10: 40602 | F10: =VLOOKUP(E10,A:B,2,TRUE) -> 1.59 | G10: =(F10-F9)/F9 -> -0.01242236 | I10: 43465 | J10: =VLOOKUP(I10, E:F, 2, TRUE) -> 22.19 | K10: =(J10-J9)/J9 -> 0.068882466
A11: 40372 | B11: 1.21 | C11: =(TSLA[[#This Row],[Prezzi giornalieri TSLA]]-B10)/B10 -> 0.061403509 | E11: 40633 | F11: =VLOOKUP(E11,A:B,2,TRUE) -> 1.85 | G11: =(F11-F10)/F10 -> 0.16352201 | I11: 43830 | J11: =VLOOKUP(I11, E:F, 2, TRUE) -> 27.89 | K11: =(J11-J10)/J10 -> 0.25687247
A12: 40373 | B12: 1.32 | C12: =(TSLA[[#This Row],[Prezzi giornalieri TSLA]]-B11)/B11 -> 0.090909091 | E12: 40663 | F12: =VLOOKUP(E12,A:B,2,TRUE) -> 1.84 | G12: =(F12-F11)/F11 -> -0.0054054054 | I12: 44196 | J12: =VLOOKUP(I12, E:F, 2, TRUE) -> 235.22 | K12: =(J12-J11)/J11 -> 7.4338473
A13: 40374 | B13: 1.33 | C13: =(TSLA[[#This Row],[Prezzi giornalieri TSLA]]-B12)/B12 -> 0.0075757576 | E13: 40694 | F13: =VLOOKUP(E13,A:B,2,TRUE) -> 2.01 | G13: =(F13-F12)/F12 -> 0.092391304 | I13: 44561 | J13: =VLOOKUP(I13, E:F, 2, TRUE) -> 352.26 | K13: =(J13-J12)/J12 -> 0.49757674
A14: 40375 | B14: 1.38 | C14: =(TSLA[[#This Row],[Prezzi giornalieri TSLA]]-B13)/B13 -> 0.037593985 | E14: 40724 | F14: =VLOOKUP(E14,A:B,2,TRUE) -> 1.94 | G14: =(F14-F13)/F13 -> -0.034825871 | I14: 44926 | J14: =VLOOKUP(I14, E:F, 2, TRUE) -> 123.18 | K14: =(J14-J13)/J13 -> -0.65031511
... A17: 40380 | B17: 1.35 | C17: =(TSLA[[#This Row],[Prezzi giornalieri TSLA]]-B16)/B16 -> 0 | E17: 40816 | F17: =VLOOKUP(E17,A:B,2,TRUE) -> 1.63 | G17: =(F17-F16)/F16 -> -0.012121212 | I17: 46022 | J17: =VLOOKUP(I17, E:F, 2, TRUE) -> 322.05 | K17: =(J17-J16)/J16 -> -0.20253071
A18: 40381 | B18: 1.4 | C18: =(TSLA[[#This Row],[Prezzi giornalieri TSLA]]-B17)/B17 -> 0.037037037 | E18: 40847 | F18: =VLOOKUP(E18,A:B,2,TRUE) -> 1.96 | G18: =(F18-F17)/F17 -> 0.20245399
A19: 40382 | B19: 1.42 | C19: =(TSLA[[#This Row],[Prezzi giornalieri TSLA]]-B18)/B18 -> 0.014285714 | E19: 40877 | F19: =VLOOKUP(E19,A:B,2,TRUE) -> 2.18 | G19: =(F19-F18)/F18 -> 0.1122449
A20: 40385 | B20: 1.4 | C20: =(TSLA[[#This Row],[Prezzi giornalieri TSLA]]-B19)/B19 -> -0.014084507 | E20: 40908 | F20: =VLOOKUP(E20,A:B,2,TRUE) -> 1.9 | G20: =(F20-F19)/F19 -> -0.12844037
A21: 40386 | B21: 1.37 | C21: =(TSLA[[#This Row],[Prezzi giornalieri TSLA]]-B20)/B20 -> -0.021428571 | E21: 40939 | F21: =VLOOKUP(E21,A:B,2,TRUE) -> 1.94 | G21: =(F21-F20)/F20 -> 0.021052632
A22: 40387 | B22: 1.38 | C22: =(TSLA[[#This Row],[Prezzi giornalieri TSLA]]-B21)/B21 -> 0.0072992701 | E22: 40968 | F22: =VLOOKUP(E22,A:B,2,TRUE) -> 2.23 | G22: =(F22-F21)/F21 -> 0.14948454
A23: 40388 | B23: 1.36 | C23: =(TSLA[[#This Row],[Prezzi giornalieri TSLA]]-B22)/B22 -> -0.014492754 | E23: 40999 | F23: =VLOOKUP(E23,A:B,2,TRUE) -> 2.48 | G23: =(F23-F22)/F22 -> 0.11210762
A24: 40389 | B24: 1.33 | C24: =(TSLA[[#This Row],[Prezzi giornalieri TSLA]]-B23)/B23 -> -0.022058824 | E24: 41029 | F24: =VLOOKUP(E24,A:B,2,TRUE) -> 2.21 | G24: =(F24-F23)/F23 -> -0.10887097
A25: 40392 | B25: 1.39 | C25: =(TSLA[[#This Row],[Prezzi giornalieri TSLA]]-B24)/B24 -> 0.045112782 | E25: 41060 | F25: =VLOOKUP(E25,A:B,2,TRUE) -> 1.97 | G25: =(F25-F24)/F24 -> -0.10859729
A26: 40393 | B26: 1.46 | C26: =(TSLA[[#This Row],[Prezzi giornalieri TSLA]]-B25)/B25 -> 0.050359712 | E26: 41090 | F26: =VLOOKUP(E26,A:B,2,TRUE) -> 2.09 | G26: =(F26-F25)/F25 -> 0.060913706
A27: 40394 | B27: 1.42 | C27: =(TSLA[[#This Row],[Prezzi giornalieri TSLA]]-B26)/B26 -> -0.02739726 | E27: 41121 | F27: =VLOOKUP(E27,A:B,2,TRUE) -> 1.83 | G27: =(F27-F26)/F26 -> -0.12440191
A28: 40395 | B28: 1.36 | C28: =(TSLA[[#This Row],[Prezzi giornalieri TSLA]]-B27)/B27 -> -0.042253521 | E28: 41152 | F28: =VLOOKUP(E28,A:B,2,TRUE) -> 1.9 | G28: =(F28-F27)/F27 -> 0.038251366
A29: 40396 | B29: 1.31 | C29: =(TSLA[[#This Row],[Prezzi giornalieri TSLA]]-B28)/B28 -> -0.036764706 | E29: 41182 | F29: =VLOOKUP(E29,A:B,2,TRUE) -> 1.95 | G29: =(F29-F28)/F28 -> 0.026315789
... A182: 40618 | B182: 1.52 | C182: =(TSLA[[#This Row],[Prezzi giornalieri TSLA]]-B181)/B181 -> -0.0065359477 | E182: 45838 | F182: =VLOOKUP(E182,A:B,2,TRUE) -> 322.05 | G182: =(F182-F181)/F181 -> -0.070455464
A183: 40619 | B183: 1.52 | C183: =(TSLA[[#This Row],[Prezzi giornalieri TSLA]]-B182)/B182 -> 0
A184: 40620 | B184: 1.53 | C184: =(TSLA[[#This Row],[Prezzi giornalieri TSLA]]-B183)/B183 -> 0.0065789474
A185: 40623 | B185: 1.52 | C185: =(TSLA[[#This Row],[Prezzi giornalieri TSLA]]-B184)/B184 -> -0.0065359477
A186: 40624 | B186: 1.48 | C186: =(TSLA[[#This Row],[Prezzi giornalieri TSLA]]-B185)/B185 -> -0.026315789
A187: 40625 | B187: 1.48 | C187: =(TSLA[[#This Row],[Prezzi giornalieri TSLA]]-B186)/B186 -> 0
A188: 40626 | B188: 1.49 | C188: =(TSLA[[#This Row],[Prezzi giornalieri TSLA]]-B187)/B187 -> 0.0067567568
A189: 40627 | B189: 1.52 | C189: =(TSLA[[#This Row],[Prezzi giornalieri TSLA]]-B188)/B188 -> 0.020134228
A190: 40630 | B190: 1.55 | C190: =(TSLA[[#This Row],[Prezzi giornalieri TSLA]]-B189)/B189 -> 0.019736842
A191: 40631 | B191: 1.59 | C191: =(TSLA[[#This Row],[Prezzi giornalieri TSLA]]-B190)/B190 -> 0.025806452
A192: 40632 | B192: 1.58 | C192: =(TSLA[[#This Row],[Prezzi giornalieri TSLA]]-B191)/B191 -> -0.0062893082
A193: 40633 | B193: 1.85 | C193: =(TSLA[[#This Row],[Prezzi giornalieri TSLA]]-B192)/B192 -> 0.17088608
A194: 40634 | B194: 1.78 | C194: =(TSLA[[#This Row],[Prezzi giornalieri TSLA]]-B193)/B193 -> -0.037837838
...

Sheet Analisi Singole Azioni
A1: Azioni | B1: Rendimento medio mensile | C1: Deviazione standard
A2: Amazon | B2: =AVERAGE(AMZN!G3:G339) -> 0.035310429 | C2: =_xlfn.STDEV.P(AMZN!G3:G339) -> 0.16277922
A3: Microsoft | B3: =AVERAGE(MSFT!G3:G473) -> 0.023610279 | C3: =_xlfn.STDEV.P(MSFT!G3:G473) -> 0.095770736
A4: Tesla | B4: =AVERAGE(TSLA!G3:G182) -> 0.04463349 | C4: =_xlfn.STDEV.P(TSLA!G3:G182) -> 0.18250726 | F4: Matrice Di Correlazione | K4: Matrice Di Covarianza
A6: Date mensili | B6: Rendimenti mensili AMZN | C6: Rendimenti mensili MSFT | D6: Rendimenti mensili TSLA | G6: Amazon | H6: Microsoft | I6: Tesla | L6: Amazon | M6: Microsoft | N6: Tesla
A7: 40390 | B7: 0.078985905 | C7: 0.12112514 | D7: -0.16352201 | F7: Amazon | G7: 1 | K7: Amazon | L7: =VARP('Analisi Singole Azioni'!$B$7:$B$186) -> 0.0072470557 | M7: 0.0026170574 | N7: 0.0072470557
A8: 40421 | B8: 0.058868437 | C8: -0.085509473 | D8: -0.022556391 | F8: Microsoft | G8: 0.50397499 | H8: 1 | K8: Microsoft | L8: 0.0026170574 | M8: =VARP('Analisi Singole Azioni'!$C$7:$C$186) -> 0.0037196983 | N8: 0.0026170574
A9: 40451 | B9: 0.25819114 | C9: 0.043113102 | D9: 0.046153846 | F9: Tesla | G9: 0.33565608 | H9: 0.27593185 | I9: 1 | K9: Tesla | L9: 0.0072470557 | M9: 0.0030521451 | N9: =VARP('Analisi Singole Azioni'!$D$7:$D$186) -> 0.0333089
A10: 40482 | B10: 0.052018337 | C10: 0.089103596 | D10: 0.073529412
A11: 40512 | B11: 0.061550566 | C11: -0.046821094 | D11: 0.61643836
A12: 40543 | B12: 0.02622577 | C12: 0.10496381 | D12: -0.24576271 | F12: Rendimento AMZN 2024 | I12: Rendimento MSFT 2024 | L12: Rendimento TSLA 2024
A13: 40574 | B13: -0.057555556 | C13: -0.0065512401 | D13: -0.095505618 | F13: 0.44392523 | I13: 0.12928299 | L13: 0.62524147
A14: 40602 | B14: 0.021516152 | C14: -0.035798398 | D14: -0.01242236
A15: 40633 | B15: 0.039471406 | C15: -0.04494382 | D15: 0.16352201 | F15: Rendimento AMZN 2023 | I15: Rendimento MSFT 2023 | L15: Rendimento TSLA 2023
A16: 40663 | B16: 0.087048243 | C16: 0.020971867 | D16: -0.0054054054 | F16: 0.80880952 | I16: 0.5819435 | L16: 1.0172106
A17: 40694 | B17: 0.0044941525 | C17: -0.028557114 | D17: 0.092391304
A18: 40724 | B18: 0.039656312 | C18: 0.039195462 | D18: -0.034825871 | F18: Rendimento AMZN 2022 | I18: Rendimento MSFT 2022 | L18: Rendimento TSLA 2022
A19: 40755 | B19: 0.088170571 | C19: 0.054094293 | D19: -0.030927835 | F19: -0.49615216 | I19: -0.28025478 | L19: -0.65031511
A20: 40786 | B20: -0.0327611 | C20: -0.02306968 | D20: -0.12234043
A21: 40816 | B21: 0.0046461924 | C21: -0.064096386 | D21: -0.012121212
A22: 40847 | B22: -0.012579198 | C22: 0.069515963 | D22: 0.20245399
A23: 40877 | B23: -0.099386446 | C23: -0.032258065 | D23: 0.1122449
A24: 40908 | B24: -0.099797181 | C24: 0.014925373 | D24: -0.12844037
A25: 40939 | B25: 0.12328134 | C25: 0.1377451 | D25: 0.021052632
A26: 40968 | B26: -0.075858877 | C26: 0.081861267 | D26: 0.14948454
A27: 40999 | B27: 0.12699649 | C27: 0.016328156 | D27: 0.11210762
A28: 41029 | B28: 0.14512864 | C28: -0.0074451411 | D28: -0.10887097
A29: 41060 | B29: -0.081888745 | C29: -0.082510857 | D29: -0.10859729
A30: 41090 | B30: 0.072518905 | C30: 0.048192771 | D30: 0.060913706
A31: 41121 | B31: 0.02167725 | C31: -0.036535304 | D31: -0.12440191
... A186: 45838 | B186: 0.036632359 | C186: 0.043183595 | D186: -0.070455464

Sheet Ottimizzazione Portafoglio
A1: Date mensili | B1: Rendimenti mensili AMZN | C1: Rendimenti mensili MSFT | D1: Rendimenti mensili TSLA | F1: Rendimento medio mensile AMZN | G1: Rendimento medio mensile MSFT | H1: Rendimento medio mensile TSLA | J1: Matrice Di Correlazione | O1: Allocazione n | P1: Peso AMZN | Q1: Peso MSFT | R1: Peso TSLA | S1: Varianza | T1: Dev. Stad. | U1: Rendimento portafoglio
A2: 43861 | B2: 0.087063815 | C2: 0.079462265 | D2: 0.55503765 | F2: =AVERAGE(B2:B67) -> 0.016969469 | G2: =AVERAGE(C2:C67) -> 0.019831694 | H2: =AVERAGE(D2:D67) -> 0.058677862 | O2: 1 | P2: 1 | Q2: 0 | R2: 0 | S2: =P2^2*$F$8^2 + Q2^2*$G$8^2 + R2^2*$H$8^2 + 2*P2*Q2*$F$8*$G$8*$K$5 + 2*P2*R2*$F$8*$H$8*$K$6 + 2*Q2*R2*G8*$H$8*$L$6 -> 0.10653943 | T2: =SQRT(S2) -> 0.32640378 | U2: =P2*$F$5 + Q2*$G$5 + R2*$H$5 -> 0.22375641
A3: 43890 | B3: -0.062213748 | C3: -0.04568434 | D3: 0.026746599 | K3: Amazon | L3: Microsoft | M3: Tesla | O3: 2 | P3: 0.95 | Q3: 0.025 | R3: 0.025 | S3: =P3^2*$F$8^2 + Q3^2*$G$8^2 + R3^2*$H$8^2 + 2*P3*Q3*$F$8*$G$8*$K$5 + 2*P3*R3*$F$8*$H$8*$K$6 + 2*Q3*R3*G9*$H$8*$L$6 -> 0.10225181 | T3: =SQRT(S3) -> 0.31976837 | U3: =P3*$F$5 + Q3*$G$5 + R3*$H$5 -> 0.24376902
A4: 43921 | B4: 0.035020571 | C4: -0.026552103 | D4: -0.215585 | F4: Rendimento medio annualizzato AMZN | G4: Rendimento medio annualizzato MSFT | H4: Rendimento medio annualizzato TSLA | J4: Amazon | K4: 1 | O4: 3 | P4: 0.9 | Q4: 0.05 | R4: 0.05 | S4: =P4^2*$F$8^2 + Q4^2*$G$8^2 + R4^2*$H$8^2 + 2*P4*Q4*$F$8*$G$8*$K$5 + 2*P4*R4*$F$8*$H$8*$K$6 + 2*Q4*R4*G10*$H$8*$L$6 -> 0.098674115 | T4: =SQRT(S4) -> 0.31412436 | U4: =P4*$F$5 + Q4*$G$5 + R4*$H$5 -> 0.26378163
A5: 43951 | B5: 0.26890015 | C5: 0.13631537 | D5: 0.4924134 | F5: =(1 + F2)^12 - 1 -> 0.22375641 | G5: =(1 + G2)^12 - 1 -> 0.26573287 | H5: =(1 + H2)^12 - 1 -> 0.98228447 | J5: Microsoft | K5: 0.50397499 | L5: 1 | O5: 4 | P5: 0.85 | Q5: 0.075 | R5: 0.075 | S5: =P5^2*$F$8^2 + Q5^2*$G$8^2 + R5^2*$H$8^2 + 2*P5*Q5*$F$8*$G$8*$K$5 + 2*P5*R5*$F$8*$H$8*$K$6 + 2*Q5*R5*G11*$H$8*$L$6 -> 0.095806335 | T5: =SQRT(S5) -> 0.30952598 | U5: =P5*$F$5 + Q5*$G$5 + R5*$H$5 -> 0.28379425
A6: 43982 | B6: -0.012784964 | C6: 0.025405911 | D6: 0.067907155 | J6: Tesla | K6: 0.33565608 | L6: 0.27593185 | M6: 1 | O6: 5 | P6: 0.8 | Q6: 0.1 | R6: 0.1 | S6: =P6^2*$F$8^2 + Q6^2*$G$8^2 + R6^2*$H$8^2 + 2*P6*Q6*$F$8*$G$8*$K$5 + 2*P6*R6*$F$8*$H$8*$K$6 + 2*Q6*R6*G12*$H$8*$L$6 -> 0.093648471 | T6: =SQRT(S6) -> 0.30602038 | U6: =P6*$F$5 + Q6*$G$5 + R6*$H$5 -> 0.30380686
A7: 44012 | B7: 0.12956677 | C7: 0.11055419 | D7: 0.2931561 | F7: Dev. Stand. Annualizzata AMZN | G7: Dev. Stand. Annualizzata MSFT | H7: Dev. Stand. Annualizzata TSLA | O7: 6 | P7: 0.75 | Q7: 0.125 | R7: 0.125 | S7: =P7^2*$F$8^2 + Q7^2*$G$8^2 + R7^2*$H$8^2 + 2*P7*Q7*$F$8*$G$8*$K$5 + 2*P7*R7*$F$8*$H$8*$K$6 + 2*Q7*R7*G13*$H$8*$L$6 -> 0.092200524 | T7: =SQRT(S7) -> 0.30364539 | U7: =P7*$F$5 + Q7*$G$5 + R7*$H$5 -> 0.32381947
A8: 44043 | B8: 0.14711362 | C8: 0.0073853729 | D8: 0.32490624 | F8: =STDEV(B2:B67)*SQRT(12) -> 0.32640378 | G8: =STDEV(C2:C67)*SQRT(12) -> 0.22765865 | H8: =STDEV(D2:D67)*SQRT(12) -> 0.75555077 | O8: 7 | P8: 0.7 | Q8: 0.15 | R8: 0.15 | S8: =P8^2*$F$8^2 + Q8^2*$G$8^2 + R8^2*$H$8^2 + 2*P8*Q8*$F$8*$G$8*$K$5 + 2*P8*R8*$F$8*$H$8*$K$6 + 2*Q8*R8*G14*$H$8*$L$6 -> 0.091462495 | T8: =SQRT(S8) -> 0.30242767 | U8: =P8*$F$5 + Q8*$G$5 + R8*$H$5 -> 0.34383208
A9: 44074 | B9: 0.090460963 | C9: 0.10273903 | D9: 0.74156008 | O9: 8 | P9: 0.65 | Q9: 0.175 | R9: 0.175 | S9: =P9^2*$F$8^2 + Q9^2*$G$8^2 + R9^2*$H$8^2 + 2*P9*Q9*$F$8*$G$8*$K$5 + 2*P9*R9*$F$8*$H$8*$K$6 + 2*Q9*R9*G15*$H$8*$L$6 -> 0.091434382 | T9: =SQRT(S9) -> 0.30238119 | U9: =P9*$F$5 + Q9*$G$5 + R9*$H$5 -> 0.3638447
A10: 44104 | B10: -0.087578529 | C10: -0.067405355 | D10: -0.13912468 | O10: 9 | P10: 0.6 | Q10: 0.2 | R10: 0.2 | S10: =P10^2*$F$8^2 + Q10^2*$G$8^2 + R10^2*$H$8^2 + 2*P10*Q10*$F$8*$G$8*$K$5 + 2*P10*R10*$F$8*$H$8*$K$6 + 2*Q10*R10*G16*$H$8*$L$6 -> 0.092116186 | T10: =SQRT(S10) -> 0.30350648 | U10: =P10*$F$5 + Q10*$G$5 + R10*$H$5 -> 0.38385731
A11: 44135 | B11: -0.035754098 | C11: -0.037376238 | D11: -0.095454545 | O11: 10 | P11: 0.55 | Q11: 0.225 | R11: 0.225 | S11: =P11^2*$F$8^2 + Q11^2*$G$8^2 + R11^2*$H$8^2 + 2*P11*Q11*$F$8*$G$8*$K$5 + 2*P11*R11*$F$8*$H$8*$K$6 + 2*Q11*R11*G17*$H$8*$L$6 -> 0.093507907 | T11: =SQRT(S11) -> 0.30579063 | U11: =P11*$F$5 + Q11*$G$5 + R11*$H$5 -> 0.40386992
A12: 44165 | B12: 0.043439883 | C12: 0.060066855 | D12: 0.46269811 | O12: 11 | P12: 0.5 | Q12: 0.25 | R12: 0.25 | S12: =P12^2*$F$8^2 + Q12^2*$G$8^2 + R12^2*$H$8^2 + 2*P12*Q12*$F$8*$G$8*$K$5 + 2*P12*R12*$F$8*$H$8*$K$6 + 2*Q12*R12*G18*$H$8*$L$6 -> 0.095609545 | T12: =SQRT(S12) -> 0.30920793 | U12: =P12*$F$5 + Q12*$G$5 + R12*$H$5 -> 0.42388254
A13: 44196 | B13: 0.028058358 | C13: 0.039004512 | D13: 0.24323467 | O13: 12 | P13: 0.45 | Q13: 0.275 | R13: 0.275 | S13: =P13^2*$F$8^2 + Q13^2*$G$8^2 + R13^2*$H$8^2 + 2*P13*Q13*$F$8*$G$8*$K$5 + 2*P13*R13*$F$8*$H$8*$K$6 + 2*Q13*R13*G19*$H$8*$L$6 -> 0.0984211 | T13: =SQRT(S13) -> 0.31372137 | U13: =P13*$F$5 + Q13*$G$5 + R13*$H$5 -> 0.44389515
A14: 44227 | B14: -0.015576018 | C14: 0.042909838 | D14: 0.12452172 | O14: 13 | P14: 0.4 | Q14: 0.3 | R14: 0.3 | S14: =P14^2*$F$8^2 + Q14^2*$G$8^2 + R14^2*$H$8^2 + 2*P14*Q14*$F$8*$G$8*$K$5 + 2*P14*R14*$F$8*$H$8*$K$6 + 2*Q14*R14*G20*$H$8*$L$6 -> 0.10194257 | T14: =SQRT(S14) -> 0.31928447 | U14: =P14*$F$5 + Q14*$G$5 + R14*$H$5 -> 0.46390776
A15: 44255 | B15: -0.035328426 | C15: 0.0041189112 | D15: -0.14872784 | O15: 14 | P15: 0.35 | Q15: 0.325 | R15: 0.325 | S15: =P15^2*$F$8^2 + Q15^2*$G$8^2 + R15^2*$H$8^2 + 2*P15*Q15*$F$8*$G$8*$K$5 + 2*P15*R15*$F$8*$H$8*$K$6 + 2*Q15*R15*G21*$H$8*$L$6 -> 0.10617396 | T15: =SQRT(S15) -> 0.32584346 | U15: =P15*$F$5 + Q15*$G$5 + R15*$H$5 -> 0.48392038
A16: 44286 | B16: 0.00037181572 | C16: 0.014579989 | D16: -0.011235955 | O16: 15 | P16: 0.3 | Q16: 0.35 | R16: 0.35 | S16: =P16^2*$F$8^2 + Q16^2*$G$8^2 + R16^2*$H$8^2 + 2*P16*Q16*$F$8*$G$8*$K$5 + 2*P16*R16*$F$8*$H$8*$K$6 + 2*Q16*R16*G22*$H$8*$L$6 -> 0.11111527 | T16: =SQRT(S16) -> 0.33333957 | U16: =P16*$F$5 + Q16*$G$5 + R16*$H$5 -> 0.50393299
A17: 44316 | B17: 0.12066268 | C17: 0.069611074 | D17: 0.062163133 | O17: 16 | P17: 0.25 | Q17: 0.375 | R17: 0.375 | S17: =P17^2*$F$8^2 + Q17^2*$G$8^2 + R17^2*$H$8^2 + 2*P17*Q17*$F$8*$G$8*$K$5 + 2*P17*R17*$F$8*$H$8*$K$6 + 2*Q17*R17*G23*$H$8*$L$6 -> 0.11676649 | T17: =SQRT(S17) -> 0.34171112 | U17: =P17*$F$5 + Q17*$G$5 + R17*$H$5 -> 0.5239456
A18: 44347 | B18: -0.070470263 | C18: -0.007642056 | D18: -0.11869926 | O18: 17 | P18: 0.2 | Q18: 0.4 | R18: 0.4 | S18: =P18^2*$F$8^2 + Q18^2*$G$8^2 + R18^2*$H$8^2 + 2*P18*Q18*$F$8*$G$8*$K$5 + 2*P18*R18*$F$8*$H$8*$K$6 + 2*Q18*R18*G24*$H$8*$L$6 -> 0.12312763 | T18: =SQRT(S18) -> 0.35089547 | U18: =P18*$F$5 + Q18*$G$5 + R18*$H$5 -> 0.54395822
A19: 44377 | B19: 0.067355037 | C19: 0.084999793 | D19: 0.087135934 | O19: 18 | P19: 0.15 | Q19: 0.425 | R19: 0.425 | S19: =P19^2*$F$8^2 + Q19^2*$G$8^2 + R19^2*$H$8^2 + 2*P19*Q19*$F$8*$G$8*$K$5 + 2*P19*R19*$F$8*$H$8*$K$6 + 2*Q19*R19*G25*$H$8*$L$6 -> 0.13019868 | T19: =SQRT(S19) -> 0.36083055 | U19: =P19*$F$5 + Q19*$G$5 + R19*$H$5 -> 0.56397083
A20: 44408 | B20: -0.032722315 | C20: 0.051705716 | D20: 0.011034117 | O20: 19 | P20: 0.1 | Q20: 0.45 | R20: 0.45 | S20: =P20^2*$F$8^2 + Q20^2*$G$8^2 + R20^2*$H$8^2 + 2*P20*Q20*$F$8*$G$8*$K$5 + 2*P20*R20*$F$8*$H$8*$K$6 + 2*Q20*R20*G26*$H$8*$L$6 -> 0.13797966 | T20: =SQRT(S20) -> 0.37145613 | U20: =P20*$F$5 + Q20*$G$5 + R20*$H$5 -> 0.58398344
... A67: 45838 | B67: 0.036632359 | C67: 0.043183595 | D67: -0.070455464 | O67: 66 | P67: 0.2 | Q67: 0.4 | R67: 0.4 | S67: =P67^2*$F$8^2 + Q67^2*$G$8^2 + R67^2*$H$8^2 + 2*P67*Q67*$F$8*$G$8*$K$5 + 2*P67*R67*$F$8*$H$8*$K$6 + 2*Q67*R67*G73*$H$8*$L$6 -> 0.12312763 | T67: =SQRT(S67) -> 0.35089547 | U67: =P67*$F$5 + Q67*$G$5 + R67*$H$5 -> 0.54395822
O68: 67 | P68: 0.4 | Q68: 0.2 | R68: 0.4 | S68: =P68^2*$F$8^2 + Q68^2*$G$8^2 + R68^2*$H$8^2 + 2*P68*Q68*$F$8*$G$8*$K$5 + 2*P68*R68*$F$8*$H$8*$K$6 + 2*Q68*R68*G74*$H$8*$L$6 -> 0.14293738 | T68: =SQRT(S68) -> 0.3780706 | U68: =P68*$F$5 + Q68*$G$5 + R68*$H$5 -> 0.53556292
O69: 68 | P69: 0.3 | Q69: 0.3 | R69: 0.4 | S69: =P69^2*$F$8^2 + Q69^2*$G$8^2 + R69^2*$H$8^2 + 2*P69*Q69*$F$8*$G$8*$K$5 + 2*P69*R69*$F$8*$H$8*$K$6 + 2*Q69*R69*G75*$H$8*$L$6 -> 0.13219782 | T69: =SQRT(S69) -> 0.36359018 | U69: =P69*$F$5 + Q69*$G$5 + R69*$H$5 -> 0.53976057
O70: 69 | P70: 0.4 | Q70: 0.3 | R70: 0.3 | S70: =P70^2*$F$8^2 + Q70^2*$G$8^2 + R70^2*$H$8^2 + 2*P70*Q70*$F$8*$G$8*$K$5 + 2*P70*R70*$F$8*$H$8*$K$6 + 2*Q70*R70*G76*$H$8*$L$6 -> 0.10194257 | T70: =SQRT(S70) -> 0.31928447 | U70: =P70*$F$5 + Q70*$G$5 + R70*$H$5 -> 0.46390776
O71: 70 | P71: 0.3 | Q71: 0.4 | R71: 0.3 | S71: =P71^2*$F$8^2 + Q71^2*$G$8^2 + R71^2*$H$8^2 + 2*P71*Q71*$F$8*$G$8*$K$5 + 2*P71*R71*$F$8*$H$8*$K$6 + 2*Q71*R71*G77*$H$8*$L$6 -> 0.093146142 | T71: =SQRT(S71) -> 0.30519853 | U71: =P71*$F$5 + Q71*$G$5 + R71*$H$5 -> 0.46810541

Sheet Dashboard 
A1: Analisi delle azioni da inserire in portafoglio
A2: L'azione Amazon presenta un rendimento medio mensile del 3,5% con un rischio del 16,3%. Microsoft mostra un rendimento più contenuto del 2,4%, accompagnato da un rischio inferiore pari al 9,6%.
A3: Tesla, invece, si distingue per il rendimento medio più elevato (4,5%), ma anche per il rischio più alto tra i tre titoli (18,3%).
A5: Dall'analisi della matrice di correlazione emerge che, nonostante le tre società operino nel settore tecnologico, non presentano una correlazione particolarmente forte tra loro.
A6: La correlazione più significativa si riscontra tra Amazon e Microsoft, mentre Tesla mantiene un profilo di performance più indipendente.
H8: Matrice Di Correlazione | N8: Matrice Di Covarianza
I10: Amazon | J10: Microsoft | K10: Tesla | O10: Amazon | P10: Microsoft | Q10: Tesla
H11: Amazon | I11: 1 | N11: Amazon | O11: =VARP('Analisi Singole Azioni'!$B$7:$B$186) -> 0.0072470557 | P11: 0.0026170574 | Q11: 0.0072470557
H12: Microsoft | I12: 0.50397499 | J12: 1 | N12: Microsoft | O12: 0.0026170574 | P12: =VARP('Analisi Singole Azioni'!$C$7:$C$186) -> 0.0037196983 | Q12: 0.0026170574
H13: Tesla | I13: 0.33565608 | J13: 0.27593185 | K13: 1 | N13: Tesla | O13: 0.0072470557 | P13: 0.0030521451 | Q13: =VARP('Analisi Singole Azioni'!$D$7:$D$186) -> 0.0333089
A15: Focus sugli anni recenti
A16: Un'analisi più dettagliata degli ultimi anni rivela dinamiche interessanti:
A17: 2022 – Anno di crisi: tutte e tre le società hanno registrato performance negative a causa dell'aumento dei tassi di interesse. In questo contesto difficile, Microsoft si è dimostrata la più resiliente con una perdita del -28,0%,
A18: contro il -49,6% di Amazon e il -65,0% di Tesla.
A19: 2023 e 2024 – Anni di recupero: entrambi gli anni hanno visto una ripresa generalizzata. Tesla ha ottenuto le performance migliori, con un impressionante +101,7% nel 2023 e un +62,5% nel 2024. Amazon ha registrato un +80,9% nel 2023
A20: e un +44,4% nel 2024. Microsoft, pur mostrando rendimenti più moderati, ha comunque chiuso con un +58,2% nel 2023, mentre nel 2024 ha evidenziato un rallentamento con un +12,9%.
A22: Composizione e ottimizzazione del portafoglio
A23: Il portafoglio sarà composto dalle tre azioni analizzate. Per identificare la combinazione ottimale, è stata condotta una simulazione con diverse allocazioni di capitale tra i titoli, variando le proporzioni di ciascuna azione (come nella seguente tabella).
A24: In seguito, è stata svolta un'analisi per ottimizzare il portafoglio, considerando unicamente i prezzi degli ultimi 5 anni.
A48: Come si evince dal grafico, la maggior parte dei portafogli si concentra in un'area caratterizzata da un rendimento compreso tra il 20% e il 50%, con una rischio che varia tra il 20% e il 40%.
A49: Si può osservare che il portafoglio che minimizza il rischio e massimizza il rendimento presenta la seguente allocazione: Si può osservare che il portafoglio che minimizza il rischio e massimizza il rendimento presenta la seguente allocazione: Amazon 12,5%, Microsoft 75,0%, Tesla 12,5%, con un rischio atteso del 22% e un rendimento medio atteso del 35%.
A50: Amazon 12,5%, Microsoft 75,0%, Tesla 12,5%, con un rischio atteso del 22% e un rendimento medio atteso del 35%.
... A53: Un portafoglio più aggressivo potrebbe essere composto da Amazon 5,0%, Microsoft 47,5% e Tesla 47,5%. Questo portafoglio presenta un rischio atteso del 38% e un potenziale rendimento del 60%.
A55: Titoli Del Portafoglio | B55: Allocazione
A56: Amazon | B56: 0.05
A57: Microsoft | B57: 0.475
A58: Tesla | B58: 0.475
A59: Tot | B59: =SUM(B56:B58) -> 1
A74: Questo tipo di allocazione è stata consigliata basandosi sul grafico precedente che mostra la frontiere efficiente di Markowitz
A76: Va inoltre considerato che, negli ultimi anni, i rendimenti – in particolare nel settore tecnologico – sono stati particolarmente elevati.
A77: Tuttavia, tali livelli potrebbero non essere sostenibili nel lungo periodo; di conseguenza, è prudente aspettarsi che i rendimenti futuri possano risultare inferiori rispetto a quelli osservati negli ultimi anni.
